Workbook
Name Am_Sched_Mnthly: 'Amortization Schedule - Monthly'!$B$3:$F$362
Name Am_Sched_Mnthly_Mnths: 'Amortization Schedule - Monthly'!$B$3:$B$362
Name AskingPrice: 'Inputs & Summary'!$D$7
Name Bathrooms: 'Inputs & Summary'!$D$9
Name Bedrooms: 'Inputs & Summary'!$D$8
Name ExpenseGrowth: 'Inputs & Summary'!$D$96
Name IncomeGrowth: 'Inputs & Summary'!$D$95
Name ListingDate: 'Inputs & Summary'!$D$5
Name LoanAmortization: 'Inputs & Summary'!$D$41
Name LoanAmount: 'Inputs & Summary'!$P$12
Name LoanRate: 'Inputs & Summary'!$D$39
Name MillageRateGrowth: 'Inputs & Summary'!$D$99
Name PriceAppreciation: 'Inputs & Summary'!$D$97
Name PurchasePrice: 'Inputs & Summary'!$D$17
Name ReassessmentFreq: 'Inputs & Summary'!$D$72
Name RentCastRent: 'Inputs & Summary'!$D$58
Name SquareFootage: 'Inputs & Summary'!$D$10
Name StreetAddress: 'Inputs & Summary'!$D$3
Name TaxValueAppreciation: 'Inputs & Summary'!$D$98
Name Units: 'Inputs & Summary'!$D$11
Name YearBuilt: 'Inputs & Summary'!$D$6

Sheet Deal Sheet
B2: =CONCATENATE('Inputs & Summary'!D3, ", ", 'Inputs & Summary'!D4)
B3: Underwriting | G3: Sources and Uses | M3: ='Inputs & Summary'!J8 | N3: ='Inputs & Summary'!K8
C4: 12 | D4: In-Place | E4: Stabilized | G4: Sources | J4: Uses | M4: ='Inputs & Summary'!J9 | N4: ='Inputs & Summary'!K9
B5: Revenue | G5: Debt | H5: ='Inputs & Summary'!P12 | J5: Purchase Price | K5: ='Inputs & Summary'!D17 | M5: ='Inputs & Summary'!J10 | N5: ='Inputs & Summary'!K10
B6: ='Inputs & Summary'!F8 | C6: ='Inputs & Summary'!G8 | D6: =C6*$C$4 | E6: =N3*$C$4 | G6: Equity | H6: ='Inputs & Summary'!P22 | J6: ='Inputs & Summary'!N15 | K6: ='Inputs & Summary'!P15 | M6: ='Inputs & Summary'!J11 | N6: ='Inputs & Summary'!K11
B7: Vacancy | C7: ='Inputs & Summary'!G10 | D7: =C7*$C$4 | E7: =N5*$C$4 | G7: Total | H7: =SUM(H5:H6) | J7: ='Inputs & Summary'!N16 | K7: ='Inputs & Summary'!P16 | M7: ='Inputs & Summary'!J12 | N7: ='Inputs & Summary'!K12
B8: Total Rental Revenue | C8: =SUM(C6:C7) | D8: =C8*$C$4 | E8: =SUM(E6:E7) | J8: ='Inputs & Summary'!N17 | K8: ='Inputs & Summary'!P17 | M8: ='Inputs & Summary'!J13 | N8: ='Inputs & Summary'!K13
J9: ='Inputs & Summary'!N18 | K9: ='Inputs & Summary'!P18 | M9: ='Inputs & Summary'!J14 | N9: ='Inputs & Summary'!K14
J10: ='Inputs & Summary'!N21 | K10: ='Inputs & Summary'!P21 | M10: ='Inputs & Summary'!J15 | N10: ='Inputs & Summary'!K15
J11: Total | K11: =SUM(K5:K10) | M11: ='Inputs & Summary'!J16 | N11: ='Inputs & Summary'!K16
B12: Expenses | M12: ='Inputs & Summary'!J17 | N12: ='Inputs & Summary'!K17
B13: ='Inputs & Summary'!F13 | C13: ='Inputs & Summary'!G13 | D13: =IFERROR(C13*$C$4, "n/a") | E13: =IFERROR(N8*$C$4, "n/a") | G13: Deal Metrics | M13: ='Inputs & Summary'!J18 | N13: ='Inputs & Summary'!K18
B14: ='Inputs & Summary'!F14 | C14: ='Inputs & Summary'!G14 | D14: =IFERROR(C14*$C$4, "n/a") | E14: =IFERROR(N9*$C$4, "n/a") | G14: Acquisition | J14: Disposition | M14: ='Inputs & Summary'!J19 | N14: ='Inputs & Summary'!K19
B15: ='Inputs & Summary'!F15 | C15: ='Inputs & Summary'!G15 | D15: =IFERROR(C15*$C$4, "n/a") | E15: =IFERROR(N10*$C$4, "n/a") | G15: Asking Price | H15: ='Inputs & Summary'!D7 | J15: Exit Price | K15: ='Inputs & Summary'!O5 | M15: ='Inputs & Summary'!J20 | N15: ='Inputs & Summary'!K20
B16: ='Inputs & Summary'!F16 | C16: ='Inputs & Summary'!G16 | D16: =IFERROR(C16*$C$4, "n/a") | E16: =IFERROR(N11*$C$4, "n/a") | G16: Purchase Price | H16: ='Inputs & Summary'!D17 | J16: Exit Cap Rate | K16: ='Inputs & Summary'!D104 | M16: ='Inputs & Summary'!J21 | N16: ='Inputs & Summary'!K21
B17: ='Inputs & Summary'!F17 | C17: ='Inputs & Summary'!G17 | D17: =IFERROR(C17*$C$4, "n/a") | E17: =IFERROR(N12*$C$4, "n/a") | G17: In-Place Cap Rate | H17: ='Inputs & Summary'!$G$29
B18: Total Expenses | C18: =SUM(C13:C17) | D18: =SUM(D13:D17) | E18: =SUM(E13:E17) | G18: Stabilized Cap Rate (Y2) | H18: =IFERROR('Annual Proforma'!E20, "n/a")
B20: NOI | D20: =SUM(D8,D18) | E20: =SUM(E8,E18) | G20: Returns
B21: NOI Margin | D21: =IFERROR(D20/D8, "n/a") | E21: =IFERROR(E20/E8, "n/a") | G21: Unlevered | J21: Levered
G22: Unlevered IRR | H22: ='Inputs & Summary'!O6 | J22: Levered IRR | K22: ='Inputs & Summary'!P6
B23: ='Inputs & Summary'!F20 | C23: ='Inputs & Summary'!G20 | D23: =IFERROR(C23*$C$4, "n/a") | E23: =IFERROR(N15*$C$4, "n/a") | G23: Unlevered Profit | H23: ='Inputs & Summary'!O8 | J23: Levered Profit | K23: ='Inputs & Summary'!P8
G24: Unlevered MoM | H24: ='Inputs & Summary'!O7 | J24: Levered MoM | K24: ='Inputs & Summary'!P7
B25: Levered Cash Flow | D25: =SUM(D20,D23) | E25: =SUM(E20,E23)
B26: Cash on Cash | D26: =D25/'Inputs & Summary'!$P$22 | E26: =E25/'Inputs & Summary'!$P$22

Sheet Inputs & Summary
B2: Property Details | F2: Unit Mix | In-Place | J2: Unit Mix | Stabilized | K2: =D57 | N2: Deal Level Returns | R2: Rate Buy Down Sensitivity Analysis
A3: x | B3: Street Address | D3: 123 Main St | F3: Unit Type | G3: Rent | J3: Unit Type | K3: Rent | O3: Unlevered | P3: Levered | R3: Discount | U3: Cash Flow | V3: Cash Flow
A4: x | B4: City, State | D4: Charlotte, NC | F4: =D8&" bd + "&D9&" ba" | G4: =D56 | J4: =F4 | K4: =D63 | N4: Exit Year | O4: =D102/12 | R4: Points | S4: Final Rate | T4: Cost | U4: (Comprehensive) | V4: (Routine Month) | W4: Levered IRR
A5: x | B5: Listing Date | D5: x/xx/xxxx | F5: Total | G5: =SUM(G4:G4) | H5: =IFERROR(G5/#REF!,"") | J5: Total | K5: =SUM(K4:K4) | N5: Exit Price | O5: =IFERROR(D17*(1+D97)^(D102/12), "n/a") | R5: 0 | S5: 0.0725 | T5: 0 | U5: - | V5: - | W5: -
A6: x | B6: Year Built | D6: 1978 | N6: IRR | O6: =IFERROR('Monthly Proforma'!C45, "n/a") | P6: =IFERROR('Monthly Proforma'!$C$65, "n/a") | R6: 1 | S6: =S5-0.00125 | T6: 1230 | U6: - | V6: - | W6: -
A7: x | B7: Asking Price | D7: 120000 | F7: Monthly Proforma | In-Place | G7: $ | H7: % | J7: Monthly Proforma | Stabilized | K7: $ | L7: % | N7: Equity Multiple | O7: =IFERROR('Monthly Proforma'!$C$46, "n/a") | P7: =IFERROR('Monthly Proforma'!C66, "n/a") | R7: 2 | S7: =S6-0.00125 | T7: 3128 | U7: - | V7: - | W7: -
A8: x | B8: Bedrooms | D8: x | F8: Rental Income | G8: =G5 | J8: Rental Income | K8: =K5 | N8: Net Profit | O8: =IFERROR('Monthly Proforma'!C47, "n/a") | P8: =IFERROR('Monthly Proforma'!C67, "n/a") | R8: 3 | S8: =S7-0.00125 | T8: 5027 | U8: - | V8: - | W8: -
A9: x | B9: Bathrooms | D9: x | F9: Potential Gross Income | G9: =SUM(G8:G8) | H9: 1 | J9: Potential Gross Income | K9: =SUM(K8:K8) | L9: 1 | N9: Peak Equity | O9: =IFERROR('Monthly Proforma'!C48, "n/a") | P9: =IFERROR('Monthly Proforma'!C68, "n/a") | R9: 4 | S9: 0.0675 | T9: 6925 | U9: - | V9: - | W9: -
A10: x | B10: Total Square Footage | D10: x | J10: (-) General Vacancy | K10: =K8*L10 | L10: =-D88 | R10: 5 | S10: 0.06625 | T10: 8824 | U10: - | V10: - | W10: -
A11: x | B11: Units | D11: x | F11: (-) Concessions | G11: 0 | H11: =IFERROR(G11/G$9, "n/a") | J11: (-) Concessions | K11: =-D91 | L11: =IFERROR(K11/K$9, "n/a") | N11: Equity Summary | R11: 6 | S11: 0.065 | T11: 10798 | U11: - | V11: - | W11: -
A12: x | B12: Type | D12: x | F12: Effective Gross Income | G12: =SUM(G9:G11) | H12: =IFERROR(G12/$G$9, "n/a") | J12: Effective Gross Income | K12: =SUM(K9:K11) | L12: =IFERROR(K12/K$9, "n/a") | N12: Loan Amount | P12: =IFERROR(D17*D34, "n/a") | R12: 7 | S12: 0.06375 | T12: 13051 | U12: - | V12: - | W12: -
B13: Lot Size (Acres) | D13: x | F13: (-) Property Taxes | G13: =IFERROR(-(D70*D68*(D69/1000))/12, "n/a") | H13: =IFERROR(G13/$G$9, "n/a") | J13: (-) Property Taxes | K13: =IFERROR(INDEX('Monthly Proforma'!E16:DT16, MATCH($K$2, 'Monthly Proforma'!E$8:DT$8, 0)), "n/a") | L13: =IFERROR(K13/K$9, "n/a") | R13: 8 | S13: 0.0625 | T13: 15536 | U13: - | V13: - | W13: -
B14: Interior/Reno Grade | D14: x | F14: (-) Insurance | G14: =IFERROR(-(((D10*D76)/100)*D77*MIN(1.6, (1+D78+D79))*(1+D80))/12, "n/a") | H14: =IFERROR(G14/$G$9, "n/a") | J14: (-) Insurance | K14: =IFERROR(INDEX('Monthly Proforma'!E17:DT17, MATCH($K$2, 'Monthly Proforma'!E$8:DT$8, 0)), "n/a") | L14: =IFERROR(K14/K$9, "n/a") | N14: Initial Equity (Down Payment) | P14: =IFERROR(D17-P12, "n/a") | R14: 9 | S14: 0.06125 | T14: 18463 | U14: - | V14: - | W14: -
F15: (-) Management | G15: =G12*H15 | H15: =-D89 | J15: (-) Management | K15: =IFERROR(INDEX('Monthly Proforma'!E18:DT18, MATCH($K$2, 'Monthly Proforma'!E$8:DT$8, 0)), "n/a") | L15: =H15 | N15: Financing Fees | P15: =IFERROR(D47+D40+D49, "n/a") | R15: 10 | S15: =S14-0.00125 | T15: 21627 | U15: - | V15: - | W15: -
B16: Purchase Assumptions | F16: (-) Utilities & HOA Dues | G16: =-D90 | H16: =IFERROR(G16/$G$9, "n/a") | J16: (-) Utilities & HOA Dues | K16: =IFERROR(INDEX('Monthly Proforma'!E19:DT19, MATCH($K$2, 'Monthly Proforma'!E$8:DT$8, 0)), "n/a") | L16: =IFERROR(K16/K$9, "n/a") | N16: Closing Costs (Non-Financing) | P16: =IFERROR(D23, "n/a") | R16: ^Property-specific buy-down grid provided by PRMG on 4/22/2026, assumes 5-year prepay penalty period and a base 1.0x DSCR (lender's methodology) before any buy-downs | W16: ^Assumes exit in Yx with x% annualized price appreciation
A17: x | B17: Purchase Price | D17: $x | F17: (-) Maintenance & Repairs | G17: =IFERROR(-((D10*D83)+(D11*D84))/12, "n/a") | H17: =IFERROR(G17/$G$9, "n/a") | J17: (-) Maintenance & Repairs | K17: =IFERROR(INDEX('Monthly Proforma'!E20:DT20, MATCH($K$2, 'Monthly Proforma'!E$8:DT$8, 0)), "n/a") | L17: =IFERROR(K17/K$9, "n/a") | N17: Net Buyer's Agent Fee | P17: =IFERROR((D21-D27)*D17, "n/a")
B18: Purchase Price Discount | D18: =IFERROR(($D$7-D17)/$D$7, "n/a") | F18: (-) Advertising, Admin & Payroll | G18: =-D92 | H18: =IFERROR(G18/$G$9, "n/a") | J18: (-) Advertising, Admin & Payroll | K18: =IFERROR(INDEX('Monthly Proforma'!E21:DT21, MATCH($K$2, 'Monthly Proforma'!E$8:DT$8, 0)), "n/a") | L18: =IFERROR(K18/K$9, "n/a") | N18: Seller Concessions | P18: =-D28
B19: Price/SF | D19: =IFERROR(D17/D10, "n/a") | F19: Net Operating Income | G19: =SUM(G12:G18) | H19: =IFERROR(G19/$G$9, "n/a") | J19: Net Operating Income | K19: =SUM(K12:K18) | L19: =IFERROR(K19/K$9, "n/a") | N19: Cash to Close (Ex-Prepaids) | P19: =IFERROR(SUM(P14:P18), "n/a")
A20: x | B20: Closing Date | D20: =TODAY()+30 | F20: (-) Debt Service | G20: =IFERROR(IF($D$43="Yes",-$D$45,-$D$42), "n/a") | J20: (-) Debt Service | K20: =IFERROR(-D42, "n/a")
B21: Buyer's Agent Fee (% of PP) | D21: 0.025 | F21: Cash Flow (Comprehensive) | G21: =IFERROR(G19+G20, "n/a") | J21: Cash Flow (Comprehensive) | K21: =IFERROR(K19+K20, "n/a") | N21: Net CapEx (Post-Closing) | P21: =IFERROR((D52-D26)+D53, "n/a")
B22: Survey Required? | D22: No | F22: Cash Flow (Routine Month) | G22: =IFERROR((G8+G13+G14+G15+G16+G18)+G20, "n/a") | J22: Cash Flow (Routine Month) | K22: =IFERROR((K8+K13+K14+K15+K16+K18)+K20, "n/a") | N22: Total Cash Required | P22: =IFERROR(SUM(P14:P18)+P21, "n/a")
B23: Closing Costs (Non-Financing) | D23: =IFERROR(700+IF(D11=1, 0, IF(D11<5, (D11-1)*300, (D11-1)*120))+995+394+50+IF(D22="Yes", 800, 0)+(0.0025*D17), "n/a") | N23: All-In Transaction Size | P23: =IFERROR(LoanAmount+P22, "n/a")
F24: DSCR (Comprehensive) | G24: =IFERROR(G19/-G20, "n/a") | J24: DSCR (Comprehensive) | K24: =IFERROR(K19/-K20, "n/a")
B25: Offer Structure Assumptions (% of Cost) | F25: DSCR (Lender) | G25: =IFERROR((G8+G13+G14)/-G20, "n/a") | J25: DSCR (Lender) | K25: =IFERROR((K8+K13+K14)/-K20, "n/a") | N25: Qualitative Notes
A26: x | B26: Repairs by Seller Pre-Closing | D26: 0 | F26: Cash on Cash (Comprehensive) | G26: =IFERROR((G21*12)/$P$22, "n/a") | J26: Cash on Cash (Comprehensive) | K26: =IFERROR((K21*12)/$P$22, "n/a") | N26: -X
A27: x | B27: Agent Fee Paid by Seller (% of PP) | D27: 0.025 | F27: Cash on Cash (Routine Month) | G27: =IFERROR((G22*12)/$P$22, "n/a") | J27: Cash on Cash (Routine Month) | K27: =IFERROR((K22*12)/$P$22, "n/a")
A28: x | B28: Seller Concessions | D28: 0
B29: Seller Concessions / PP | D29: =IFERROR(D28/D17, "n/a") | F29: Cap Rate | G29: =IFERROR((G19*12)/$D$17, "n/a") | H29: =IFERROR((G19*12)/$P$23, "n/a") | J29: Cap Rate | K29: =IFERROR((K19*12)/$D$17, "n/a") | L29: =IFERROR((K19*12)/$P$23, "n/a")
B30: Net Offer Amount | D30: =IFERROR(D17-(D26+(D27*D17)+D28), "n/a") | F30: Loan Factor Rate | G30: =IFERROR((G20*12)/$P$12, "n/a") | J30: Loan Factor Rate | K30: =IFERROR((K20*12)/$P$12, "n/a")
B31: Net Offer Amount Discount | D31: =IFERROR(($D$7-D30)/$D$7, "n/a") | F31: Spread | G31: =IFERROR(G29+G30, "n/a") | J31: Spread | K31: =IFERROR(K29+K30, "n/a")
B33: Debt Assumptions
B34: LTPP | D34: 0.75
A35: x | B35: Base Interest Rate | D35: 0.0725
A36: x | B36: Discount Points | D36: 0
A37: x | B37: Cost per Point (% of Loan) | D37: =IFERROR((T13/R13)/LoanAmount, "n/a")
B38: Rate Reduction per Point | D38: 0.00125
B39: Final Interest Rate | D39: =D35-(D36*D38)
B40: Total Rate Buydown Cost | D40: =IFERROR(D36*(D37*P12), "n/a")
B41: Amortization (Years) | D41: 30
B42: Monthly Payment | D42: =IFERROR(PMT(D39/12,D41*12,-P12), "n/a")
...

Sheet Data Validation
A1: Single Family | B1: A
A2: Multi-Family | B2: B
A3: Townhouse | B3: C
A4: Manufactured
A5: Condo/Apartment

Sheet Monthly Proforma
C1: Reassessment Year | D1: {=INDEX(E8:DT8, MATCH(1, ('Inputs & Summary'!D71=YEAR(E6:DT6))*(1=MONTH(E6:DT6)), 0))} | E1: =IF(MOD(E$8-$D$1, (ReassessmentFreq*12))=0, "x", "") | F1: =IF(MOD(F$8-$D$1, (ReassessmentFreq*12))=0, "x", "") | G1: =IF(MOD(G$8-$D$1, (ReassessmentFreq*12))=0, "x", "") | H1: =IF(MOD(H$8-$D$1, (ReassessmentFreq*12))=0, "x", "") | I1: =IF(MOD(I$8-$D$1, (ReassessmentFreq*12))=0, "x", "") | J1: =IF(MOD(J$8-$D$1, (ReassessmentFreq*12))=0, "x", "") | K1: =IF(MOD(K$8-$D$1, (ReassessmentFreq*12))=0, "x", "") | L1: =IF(MOD(L$8-$D$1, (ReassessmentFreq*12))=0, "x", "") | ... DT1: =IF(MOD(DT$8-$D$1, (ReassessmentFreq*12))=0, "x", "")
C2: Assessed Value | D2: ='Inputs & Summary'!D70 | E2: =IF(E$8=$D$1, MAX(D2, PurchasePrice)*((1+TaxValueAppreciation)^($D$1/12)), IF(E$1="x", D2*((1+TaxValueAppreciation)^ReassessmentFreq),D2)) | F2: =IF(F$8=$D$1, MAX(E2, PurchasePrice)*((1+TaxValueAppreciation)^($D$1/12)), IF(F$1="x", E2*((1+TaxValueAppreciation)^ReassessmentFreq),E2)) | G2: =IF(G$8=$D$1, MAX(F2, PurchasePrice)*((1+TaxValueAppreciation)^($D$1/12)), IF(G$1="x", F2*((1+TaxValueAppreciation)^ReassessmentFreq),F2)) | H2: =IF(H$8=$D$1, MAX(G2, PurchasePrice)*((1+TaxValueAppreciation)^($D$1/12)), IF(H$1="x", G2*((1+TaxValueAppreciation)^ReassessmentFreq),G2)) | I2: =IF(I$8=$D$1, MAX(H2, PurchasePrice)*((1+TaxValueAppreciation)^($D$1/12)), IF(I$1="x", H2*((1+TaxValueAppreciation)^ReassessmentFreq),H2)) | J2: =IF(J$8=$D$1, MAX(I2, PurchasePrice)*((1+TaxValueAppreciation)^($D$1/12)), IF(J$1="x", I2*((1+TaxValueAppreciation)^ReassessmentFreq),I2)) | K2: =IF(K$8=$D$1, MAX(J2, PurchasePrice)*((1+TaxValueAppreciation)^($D$1/12)), IF(K$1="x", J2*((1+TaxValueAppreciation)^ReassessmentFreq),J2)) | L2: =IF(L$8=$D$1, MAX(K2, PurchasePrice)*((1+TaxValueAppreciation)^($D$1/12)), IF(L$1="x", K2*((1+TaxValueAppreciation)^ReassessmentFreq),K2)) | ... DT2: =IF(DT$8=$D$1, MAX(DS2, PurchasePrice)*((1+TaxValueAppreciation)^($D$1/12)), IF(DT$1="x", DS2*((1+TaxValueAppreciation)^ReassessmentFreq),DS2))
C3: Millage Rate | D3: ='Inputs & Summary'!D69 | E3: =IF(E$1="x", D3*((1+MillageRateGrowth)^ReassessmentFreq),D3) | F3: =IF(F$1="x", E3*((1+MillageRateGrowth)^ReassessmentFreq),E3) | G3: =IF(G$1="x", F3*((1+MillageRateGrowth)^ReassessmentFreq),F3) | H3: =IF(H$1="x", G3*((1+MillageRateGrowth)^ReassessmentFreq),G3) | I3: =IF(I$1="x", H3*((1+MillageRateGrowth)^ReassessmentFreq),H3) | J3: =IF(J$1="x", I3*((1+MillageRateGrowth)^ReassessmentFreq),I3) | K3: =IF(K$1="x", J3*((1+MillageRateGrowth)^ReassessmentFreq),J3) | L3: =IF(L$1="x", K3*((1+MillageRateGrowth)^ReassessmentFreq),K3) | ... DT3: =IF(DT$1="x", DS3*((1+MillageRateGrowth)^ReassessmentFreq),DS3)
C4: Purchase Anniversary | E4: =IF(AND(MOD(E$8-13, 12)=0, E$8>=13), "x", "") | F4: =IF(AND(MOD(F$8-13, 12)=0, F$8>=13), "x", "") | G4: =IF(AND(MOD(G$8-13, 12)=0, G$8>=13), "x", "") | H4: =IF(AND(MOD(H$8-13, 12)=0, H$8>=13), "x", "") | I4: =IF(AND(MOD(I$8-13, 12)=0, I$8>=13), "x", "") | J4: =IF(AND(MOD(J$8-13, 12)=0, J$8>=13), "x", "") | K4: =IF(AND(MOD(K$8-13, 12)=0, K$8>=13), "x", "") | L4: =IF(AND(MOD(L$8-13, 12)=0, L$8>=13), "x", "") | ... DT4: =IF(AND(MOD(DT$8-13, 12)=0, DT$8>=13), "x", "")
C5: Stabalization Anniversary | D5: ='Inputs & Summary'!D57 | E5: =IF(AND(MOD(E$8-$D$5, 12)=0, E$8>=$D$5), "x", "") | F5: =IF(AND(MOD(F$8-$D$5, 12)=0, F$8>=$D$5), "x", "") | G5: =IF(AND(MOD(G$8-$D$5, 12)=0, G$8>=$D$5), "x", "") | H5: =IF(AND(MOD(H$8-$D$5, 12)=0, H$8>=$D$5), "x", "") | I5: =IF(AND(MOD(I$8-$D$5, 12)=0, I$8>=$D$5), "x", "") | J5: =IF(AND(MOD(J$8-$D$5, 12)=0, J$8>=$D$5), "x", "") | K5: =IF(AND(MOD(K$8-$D$5, 12)=0, K$8>=$D$5), "x", "") | L5: =IF(AND(MOD(L$8-$D$5, 12)=0, L$8>=$D$5), "x", "") | ... DT5: =IF(AND(MOD(DT$8-$D$5, 12)=0, DT$8>=$D$5), "x", "")
C6: Date | D6: ='Inputs & Summary'!$D$20 | E6: =EOMONTH(D6,1) | F6: =EOMONTH(E6,1) | G6: =EOMONTH(F6,1) | H6: =EOMONTH(G6,1) | I6: =EOMONTH(H6,1) | J6: =EOMONTH(I6,1) | K6: =EOMONTH(J6,1) | L6: =EOMONTH(K6,1) | ... DT6: =EOMONTH(DS6,1)
C7: Year | D7: 0 | E7: =ROUNDUP(E8/12,0) | F7: =ROUNDUP(F8/12,0) | G7: =ROUNDUP(G8/12,0) | H7: =ROUNDUP(H8/12,0) | I7: =ROUNDUP(I8/12,0) | J7: =ROUNDUP(J8/12,0) | K7: =ROUNDUP(K8/12,0) | L7: =ROUNDUP(L8/12,0) | ... DT7: =ROUNDUP(DT8/12,0)
C8: Month | D8: 0 | E8: =D8+1 | F8: =E8+1 | G8: =F8+1 | H8: =G8+1 | I8: =H8+1 | J8: =I8+1 | K8: =J8+1 | L8: =K8+1 | ... DT8: =DS8+1
B9: Unit Mix & Lease-Up | C9: In-Place Rent | D9: Stabilized Rent
B10: ='Inputs & Summary'!F4 | C10: ='Inputs & Summary'!G4 | D10: ='Inputs & Summary'!K4 | E10: =IF(E$8=$D5,$D10,IF(E$8=1,$C10,IF(E$5="x", D10*(1+IncomeGrowth), D10))) | F10: =IF(F$8=$D5,$D10,IF(F$8=1,$C10,IF(F$5="x", E10*(1+IncomeGrowth), E10))) | G10: =IF(G$8=$D5,$D10,IF(G$8=1,$C10,IF(G$5="x", F10*(1+IncomeGrowth), F10))) | H10: =IF(H$8=$D5,$D10,IF(H$8=1,$C10,IF(H$5="x", G10*(1+IncomeGrowth), G10))) | I10: =IF(I$8=$D5,$D10,IF(I$8=1,$C10,IF(I$5="x", H10*(1+IncomeGrowth), H10))) | J10: =IF(J$8=$D5,$D10,IF(J$8=1,$C10,IF(J$5="x", I10*(1+IncomeGrowth), I10))) | K10: =IF(K$8=$D5,$D10,IF(K$8=1,$C10,IF(K$5="x", J10*(1+IncomeGrowth), J10))) | L10: =IF(L$8=$D5,$D10,IF(L$8=1,$C10,IF(L$5="x", K10*(1+IncomeGrowth), K10))) | ... DT10: =IF(DT$8=$D5,$D10,IF(DT$8=1,$C10,IF(DT$5="x", DS10*(1+IncomeGrowth), DS10)))
B11: (+) Rental Income | E11: =SUM(E10:E10) | F11: =SUM(F10:F10) | G11: =SUM(G10:G10) | H11: =SUM(H10:H10) | I11: =SUM(I10:I10) | J11: =SUM(J10:J10) | K11: =SUM(K10:K10) | L11: =SUM(L10:L10) | ... DT11: =SUM(DT10:DT10)
B12: Potential Gross Income | E12: =SUM(E11:E11) | F12: =SUM(F11:F11) | G12: =SUM(G11:G11) | H12: =SUM(H11:H11) | I12: =SUM(I11:I11) | J12: =SUM(J11:J11) | K12: =SUM(K11:K11) | L12: =SUM(L11:L11) | ... DT12: =SUM(DT11:DT11)
B13: (-) General Vacancy | D13: =-'Inputs & Summary'!D88 | E13: =E12*$D$13 | F13: =F12*$D$13 | G13: =G12*$D$13 | H13: =H12*$D$13 | I13: =I12*$D$13 | J13: =J12*$D$13 | K13: =K12*$D$13 | L13: =L12*$D$13 | ... DT13: =DT12*$D$13
B14: (-) Concessions | D14: =-'Inputs & Summary'!L11 | E14: =E12*-$D$14 | F14: =F12*-$D$14 | G14: =G12*-$D$14 | H14: =H12*-$D$14 | I14: =I12*-$D$14 | J14: =J12*-$D$14 | K14: =K12*-$D$14 | L14: =L12*-$D$14 | ... DT14: =DT12*-$D$14
B15: Effective Gross Income | E15: =SUM(E12:E14) | F15: =SUM(F12:F14) | G15: =SUM(G12:G14) | H15: =SUM(H12:H14) | I15: =SUM(I12:I14) | J15: =SUM(J12:J14) | K15: =SUM(K12:K14) | L15: =SUM(L12:L14) | ... DT15: =SUM(DT12:DT14)
B16: (-) Property Taxes | D16: ='Inputs & Summary'!G13 | E16: =-(E2*'Inputs & Summary'!$D$68*(E3/1000))/12 | F16: =-(F2*'Inputs & Summary'!$D$68*(F3/1000))/12 | G16: =-(G2*'Inputs & Summary'!$D$68*(G3/1000))/12 | H16: =-(H2*'Inputs & Summary'!$D$68*(H3/1000))/12 | I16: =-(I2*'Inputs & Summary'!$D$68*(I3/1000))/12 | J16: =-(J2*'Inputs & Summary'!$D$68*(J3/1000))/12 | K16: =-(K2*'Inputs & Summary'!$D$68*(K3/1000))/12 | L16: =-(L2*'Inputs & Summary'!$D$68*(L3/1000))/12 | ... DT16: =-(DT2*'Inputs & Summary'!$D$68*(DT3/1000))/12
B17: (-) Insurance | D17: ='Inputs & Summary'!G14 | E17: =IF(E$4="x", D17*(1+ExpenseGrowth),D17) | F17: =IF(F$4="x", E17*(1+ExpenseGrowth),E17) | G17: =IF(G$4="x", F17*(1+ExpenseGrowth),F17) | H17: =IF(H$4="x", G17*(1+ExpenseGrowth),G17) | I17: =IF(I$4="x", H17*(1+ExpenseGrowth),H17) | J17: =IF(J$4="x", I17*(1+ExpenseGrowth),I17) | K17: =IF(K$4="x", J17*(1+ExpenseGrowth),J17) | L17: =IF(L$4="x", K17*(1+ExpenseGrowth),K17) | ... DT17: =IF(DT$4="x", DS17*(1+ExpenseGrowth),DS17)
B18: (-) Management | D18: =-'Inputs & Summary'!D89 | E18: =E10*$D$18 | F18: =F10*$D$18 | G18: =G10*$D$18 | H18: =H10*$D$18 | I18: =I10*$D$18 | J18: =J10*$D$18 | K18: =K10*$D$18 | L18: =L10*$D$18 | ... DT18: =DT10*$D$18
B19: (-) Utilities & HOA Dues | D19: ='Inputs & Summary'!G16 | E19: =IF(MONTH(E$6)=1, D19*(1+ExpenseGrowth),D19) | F19: =IF(MONTH(F$6)=1, E19*(1+ExpenseGrowth),E19) | G19: =IF(MONTH(G$6)=1, F19*(1+ExpenseGrowth),F19) | H19: =IF(MONTH(H$6)=1, G19*(1+ExpenseGrowth),G19) | I19: =IF(MONTH(I$6)=1, H19*(1+ExpenseGrowth),H19) | J19: =IF(MONTH(J$6)=1, I19*(1+ExpenseGrowth),I19) | K19: =IF(MONTH(K$6)=1, J19*(1+ExpenseGrowth),J19) | L19: =IF(MONTH(L$6)=1, K19*(1+ExpenseGrowth),K19) | ... DT19: =IF(MONTH(DT$6)=1, DS19*(1+ExpenseGrowth),DS19)
B20: (-) Maintenance & Repairs | D20: ='Inputs & Summary'!G17 | E20: =D20*(1+(ExpenseGrowth/12)) | F20: =E20*(1+(ExpenseGrowth/12)) | G20: =F20*(1+(ExpenseGrowth/12)) | H20: =G20*(1+(ExpenseGrowth/12)) | I20: =H20*(1+(ExpenseGrowth/12)) | J20: =I20*(1+(ExpenseGrowth/12)) | K20: =J20*(1+(ExpenseGrowth/12)) | L20: =K20*(1+(ExpenseGrowth/12)) | ... DT20: =DS20*(1+(ExpenseGrowth/12))
B21: (-) Advertising, Admin & Payroll | D21: ='Inputs & Summary'!G18 | E21: =IF(MONTH(E$6)=1, D21*(1+ExpenseGrowth),D21) | F21: =IF(MONTH(F$6)=1, E21*(1+ExpenseGrowth),E21) | G21: =IF(MONTH(G$6)=1, F21*(1+ExpenseGrowth),F21) | H21: =IF(MONTH(H$6)=1, G21*(1+ExpenseGrowth),G21) | I21: =IF(MONTH(I$6)=1, H21*(1+ExpenseGrowth),H21) | J21: =IF(MONTH(J$6)=1, I21*(1+ExpenseGrowth),I21) | K21: =IF(MONTH(K$6)=1, J21*(1+ExpenseGrowth),J21) | L21: =IF(MONTH(L$6)=1, K21*(1+ExpenseGrowth),K21) | ... DT21: =IF(MONTH(DT$6)=1, DS21*(1+ExpenseGrowth),DS21)
B22: Net Operating Income | E22: =E15+SUM(E16:E21) | F22: =F15+SUM(F16:F21) | G22: =G15+SUM(G16:G21) | H22: =H15+SUM(H16:H21) | I22: =I15+SUM(I16:I21) | J22: =J15+SUM(J16:J21) | K22: =K15+SUM(K16:K21) | L22: =L15+SUM(L16:L21) | ... DT22: =DT15+SUM(DT16:DT21)
B23: NOI Margin | E23: =IFERROR(E22/E12, "n/a") | F23: =IFERROR(F22/F12, "n/a") | G23: =IFERROR(G22/G12, "n/a") | H23: =IFERROR(H22/H12, "n/a") | I23: =IFERROR(I22/I12, "n/a") | J23: =IFERROR(J22/J12, "n/a") | K23: =IFERROR(K22/K12, "n/a") | L23: =IFERROR(L22/L12, "n/a") | ... DT23: =IFERROR(DT22/DT12, "n/a")
B24: (-) Debt Service | D24: ='Inputs & Summary'!$G$20 | E24: =IF(AND('Inputs & Summary'!$D$43="Yes",E$8<='Inputs & Summary'!$D$44),-'Inputs & Summary'!$D$45,-'Inputs & Summary'!$D$42) | F24: =IF(AND('Inputs & Summary'!$D$43="Yes",F$8<='Inputs & Summary'!$D$44),-'Inputs & Summary'!$D$45,-'Inputs & Summary'!$D$42) | G24: =IF(AND('Inputs & Summary'!$D$43="Yes",G$8<='Inputs & Summary'!$D$44),-'Inputs & Summary'!$D$45,-'Inputs & Summary'!$D$42) | H24: =IF(AND('Inputs & Summary'!$D$43="Yes",H$8<='Inputs & Summary'!$D$44),-'Inputs & Summary'!$D$45,-'Inputs & Summary'!$D$42) | I24: =IF(AND('Inputs & Summary'!$D$43="Yes",I$8<='Inputs & Summary'!$D$44),-'Inputs & Summary'!$D$45,-'Inputs & Summary'!$D$42) | J24: =IF(AND('Inputs & Summary'!$D$43="Yes",J$8<='Inputs & Summary'!$D$44),-'Inputs & Summary'!$D$45,-'Inputs & Summary'!$D$42) | K24: =IF(AND('Inputs & Summary'!$D$43="Yes",K$8<='Inputs & Summary'!$D$44),-'Inputs & Summary'!$D$45,-'Inputs & Summary'!$D$42) | L24: =IF(AND('Inputs & Summary'!$D$43="Yes",L$8<='Inputs & Summary'!$D$44),-'Inputs & Summary'!$D$45,-'Inputs & Summary'!$D$42) | ... DT24: =IF(AND('Inputs & Summary'!$D$43="Yes",DT$8<='Inputs & Summary'!$D$44),-'Inputs & Summary'!$D$45,-'Inputs & Summary'!$D$42)
B25: Monthly Cash Flow | E25: =E22+E24 | F25: =F22+F24 | G25: =G22+G24 | H25: =H22+H24 | I25: =I22+I24 | J25: =J22+J24 | K25: =K22+K24 | L25: =L22+L24 | ... DT25: =DT22+DT24
B26: DSCR | E26: =E22/-E24 | F26: =F22/-F24 | G26: =G22/-G24 | H26: =H22/-H24 | I26: =I22/-I24 | J26: =J22/-J24 | K26: =K22/-K24 | L26: =L22/-L24 | ... DT26: =DT22/-DT24
B28: Unlevered Cash Flow
B29: (-) Purchase Price | D29: =-PurchasePrice | E29: 0 | F29: 0 | G29: 0 | H29: 0 | I29: 0 | J29: 0 | K29: 0 | L29: 0 | M29: 0 | N29: 0 | O29: 0 | P29: 0 | Q29: 0 | R29: 0 | S29: 0 | T29: 0 | U29: 0 | V29: 0 | W29: 0 | X29: 0 | Y29: 0 | Z29: 0 | AA29: 0 | AB29: 0 | AC29: 0 | AD29: 0 | AE29: 0 | AF29: 0 | AG29: 0 | AH29: 0 | AI29: 0 | AJ29: 0 | AK29: 0 | AL29: 0 | AM29: 0 | AN29: 0 | AO29: 0 | AP29: 0 | AQ29: 0 | AR29: 0 | AS29: 0 | AT29: 0 | AU29: 0 | AV29: 0 | AW29: 0 | AX29: 0 | AY29: 0 | AZ29: 0 | BA29: 0 | BB29: 0 | BC29: 0 | BD29: 0 | BE29: 0 | BF29: 0 | BG29: 0 | BH29: 0 | BI29: 0 | BJ29: 0 | BK29: 0 | BL29: 0 | BM29: 0 | BN29: 0 | BO29: 0 | BP29: 0 | BQ29: 0 | BR29: 0 | BS29: 0 | BT29: 0 | BU29: 0 | BV29: 0 | BW29: 0 | BX29: 0 | BY29: 0 | BZ29: 0 | CA29: 0 | CB29: 0 | CC29: 0 | CD29: 0 | CE29: 0 | CF29: 0 | CG29: 0 | CH29: 0 | CI29: 0 | CJ29: 0 | CK29: 0 | CL29: 0 | CM29: 0 | CN29: 0 | CO29: 0 | CP29: 0 | CQ29: 0 | CR29: 0 | CS29: 0 | CT29: 0 | CU29: 0 | CV29: 0 | CW29: 0 | CX29: 0 | CY29: 0 | CZ29: 0 | DA29: 0 | DB29: 0 | DC29: 0 | DD29: 0 | DE29: 0 | DF29: 0 | DG29: 0 | DH29: 0 | DI29: 0 | DJ29: 0 | DK29: 0 | DL29: 0 | DM29: 0 | DN29: 0 | DO29: 0 | DP29: 0 | DQ29: 0 | DR29: 0 | DS29: 0 | DT29: 0
B30: ="(-) "&'Inputs & Summary'!N16 | D30: =-'Inputs & Summary'!P16 | E30: 0 | F30: 0 | G30: 0 | H30: 0 | I30: 0 | J30: 0 | K30: 0 | L30: 0 | M30: 0 | N30: 0 | O30: 0 | P30: 0 | Q30: 0 | R30: 0 | S30: 0 | T30: 0 | U30: 0 | V30: 0 | W30: 0 | X30: 0 | Y30: 0 | Z30: 0 | AA30: 0 | AB30: 0 | AC30: 0 | AD30: 0 | AE30: 0 | AF30: 0 | AG30: 0 | AH30: 0 | AI30: 0 | AJ30: 0 | AK30: 0 | AL30: 0 | AM30: 0 | AN30: 0 | AO30: 0 | AP30: 0 | AQ30: 0 | AR30: 0 | AS30: 0 | AT30: 0 | AU30: 0 | AV30: 0 | AW30: 0 | AX30: 0 | AY30: 0 | AZ30: 0 | BA30: 0 | BB30: 0 | BC30: 0 | BD30: 0 | BE30: 0 | BF30: 0 | BG30: 0 | BH30: 0 | BI30: 0 | BJ30: 0 | BK30: 0 | BL30: 0 | BM30: 0 | BN30: 0 | BO30: 0 | BP30: 0 | BQ30: 0 | BR30: 0 | BS30: 0 | BT30: 0 | BU30: 0 | BV30: 0 | BW30: 0 | BX30: 0 | BY30: 0 | BZ30: 0 | CA30: 0 | CB30: 0 | CC30: 0 | CD30: 0 | CE30: 0 | CF30: 0 | CG30: 0 | CH30: 0 | CI30: 0 | CJ30: 0 | CK30: 0 | CL30: 0 | CM30: 0 | CN30: 0 | CO30: 0 | CP30: 0 | CQ30: 0 | CR30: 0 | CS30: 0 | CT30: 0 | CU30: 0 | CV30: 0 | CW30: 0 | CX30: 0 | CY30: 0 | CZ30: 0 | DA30: 0 | DB30: 0 | DC30: 0 | DD30: 0 | DE30: 0 | DF30: 0 | DG30: 0 | DH30: 0 | DI30: 0 | DJ30: 0 | DK30: 0 | DL30: 0 | DM30: 0 | DN30: 0 | DO30: 0 | DP30: 0 | DQ30: 0 | DR30: 0 | DS30: 0 | DT30: 0
B31: ="(-) "&'Inputs & Summary'!N17 | D31: =-'Inputs & Summary'!P17 | E31: 0 | F31: 0 | G31: 0 | H31: 0 | I31: 0 | J31: 0 | K31: 0 | L31: 0 | M31: 0 | N31: 0 | O31: 0 | P31: 0 | Q31: 0 | R31: 0 | S31: 0 | T31: 0 | U31: 0 | V31: 0 | W31: 0 | X31: 0 | Y31: 0 | Z31: 0 | AA31: 0 | AB31: 0 | AC31: 0 | AD31: 0 | AE31: 0 | AF31: 0 | AG31: 0 | AH31: 0 | AI31: 0 | AJ31: 0 | AK31: 0 | AL31: 0 | AM31: 0 | AN31: 0 | AO31: 0 | AP31: 0 | AQ31: 0 | AR31: 0 | AS31: 0 | AT31: 0 | AU31: 0 | AV31: 0 | AW31: 0 | AX31: 0 | AY31: 0 | AZ31: 0 | BA31: 0 | BB31: 0 | BC31: 0 | BD31: 0 | BE31: 0 | BF31: 0 | BG31: 0 | BH31: 0 | BI31: 0 | BJ31: 0 | BK31: 0 | BL31: 0 | BM31: 0 | BN31: 0 | BO31: 0 | BP31: 0 | BQ31: 0 | BR31: 0 | BS31: 0 | BT31: 0 | BU31: 0 | BV31: 0 | BW31: 0 | BX31: 0 | BY31: 0 | BZ31: 0 | CA31: 0 | CB31: 0 | CC31: 0 | CD31: 0 | CE31: 0 | CF31: 0 | CG31: 0 | CH31: 0 | CI31: 0 | CJ31: 0 | CK31: 0 | CL31: 0 | CM31: 0 | CN31: 0 | CO31: 0 | CP31: 0 | CQ31: 0 | CR31: 0 | CS31: 0 | CT31: 0 | CU31: 0 | CV31: 0 | CW31: 0 | CX31: 0 | CY31: 0 | CZ31: 0 | DA31: 0 | DB31: 0 | DC31: 0 | DD31: 0 | DE31: 0 | DF31: 0 | DG31: 0 | DH31: 0 | DI31: 0 | DJ31: 0 | DK31: 0 | DL31: 0 | DM31: 0 | DN31: 0 | DO31: 0 | DP31: 0 | DQ31: 0 | DR31: 0 | DS31: 0 | DT31: 0
B32: ="(+) "&'Inputs & Summary'!N18 | D32: =-'Inputs & Summary'!P18 | E32: 0 | F32: 0 | G32: 0 | H32: 0 | I32: 0 | J32: 0 | K32: 0 | L32: 0 | M32: 0 | N32: 0 | O32: 0 | P32: 0 | Q32: 0 | R32: 0 | S32: 0 | T32: 0 | U32: 0 | V32: 0 | W32: 0 | X32: 0 | Y32: 0 | Z32: 0 | AA32: 0 | AB32: 0 | AC32: 0 | AD32: 0 | AE32: 0 | AF32: 0 | AG32: 0 | AH32: 0 | AI32: 0 | AJ32: 0 | AK32: 0 | AL32: 0 | AM32: 0 | AN32: 0 | AO32: 0 | AP32: 0 | AQ32: 0 | AR32: 0 | AS32: 0 | AT32: 0 | AU32: 0 | AV32: 0 | AW32: 0 | AX32: 0 | AY32: 0 | AZ32: 0 | BA32: 0 | BB32: 0 | BC32: 0 | BD32: 0 | BE32: 0 | BF32: 0 | BG32: 0 | BH32: 0 | BI32: 0 | BJ32: 0 | BK32: 0 | BL32: 0 | BM32: 0 | BN32: 0 | BO32: 0 | BP32: 0 | BQ32: 0 | BR32: 0 | BS32: 0 | BT32: 0 | BU32: 0 | BV32: 0 | BW32: 0 | BX32: 0 | BY32: 0 | BZ32: 0 | CA32: 0 | CB32: 0 | CC32: 0 | CD32: 0 | CE32: 0 | CF32: 0 | CG32: 0 | CH32: 0 | CI32: 0 | CJ32: 0 | CK32: 0 | CL32: 0 | CM32: 0 | CN32: 0 | CO32: 0 | CP32: 0 | CQ32: 0 | CR32: 0 | CS32: 0 | CT32: 0 | CU32: 0 | CV32: 0 | CW32: 0 | CX32: 0 | CY32: 0 | CZ32: 0 | DA32: 0 | DB32: 0 | DC32: 0 | DD32: 0 | DE32: 0 | DF32: 0 | DG32: 0 | DH32: 0 | DI32: 0 | DJ32: 0 | DK32: 0 | DL32: 0 | DM32: 0 | DN32: 0 | DO32: 0 | DP32: 0 | DQ32: 0 | DR32: 0 | DS32: 0 | DT32: 0
B33: ="(-) "&'Inputs & Summary'!N21 | D33: =-'Inputs & Summary'!P21 | E33: 0 | F33: 0 | G33: 0 | H33: 0 | I33: 0 | J33: 0 | K33: 0 | L33: 0 | M33: 0 | N33: 0 | O33: 0 | P33: 0 | Q33: 0 | R33: 0 | S33: 0 | T33: 0 | U33: 0 | V33: 0 | W33: 0 | X33: 0 | Y33: 0 | Z33: 0 | AA33: 0 | AB33: 0 | AC33: 0 | AD33: 0 | AE33: 0 | AF33: 0 | AG33: 0 | AH33: 0 | AI33: 0 | AJ33: 0 | AK33: 0 | AL33: 0 | AM33: 0 | AN33: 0 | AO33: 0 | AP33: 0 | AQ33: 0 | AR33: 0 | AS33: 0 | AT33: 0 | AU33: 0 | AV33: 0 | AW33: 0 | AX33: 0 | AY33: 0 | AZ33: 0 | BA33: 0 | BB33: 0 | BC33: 0 | BD33: 0 | BE33: 0 | BF33: 0 | BG33: 0 | BH33: 0 | BI33: 0 | BJ33: 0 | BK33: 0 | BL33: 0 | BM33: 0 | BN33: 0 | BO33: 0 | BP33: 0 | BQ33: 0 | BR33: 0 | BS33: 0 | BT33: 0 | BU33: 0 | BV33: 0 | BW33: 0 | BX33: 0 | BY33: 0 | BZ33: 0 | CA33: 0 | CB33: 0 | CC33: 0 | CD33: 0 | CE33: 0 | CF33: 0 | CG33: 0 | CH33: 0 | CI33: 0 | CJ33: 0 | CK33: 0 | CL33: 0 | CM33: 0 | CN33: 0 | CO33: 0 | CP33: 0 | CQ33: 0 | CR33: 0 | CS33: 0 | CT33: 0 | CU33: 0 | CV33: 0 | CW33: 0 | CX33: 0 | CY33: 0 | CZ33: 0 | DA33: 0 | DB33: 0 | DC33: 0 | DD33: 0 | DE33: 0 | DF33: 0 | DG33: 0 | DH33: 0 | DI33: 0 | DJ33: 0 | DK33: 0 | DL33: 0 | DM33: 0 | DN33: 0 | DO33: 0 | DP33: 0 | DQ33: 0 | DR33: 0 | DS33: 0 | DT33: 0
B34: Total Unlevered Costs | D34: =SUM(D29:D33)
B36: (+) Net Operating Income | E36: =E22*(E$8<='Inputs & Summary'!$D$102) | F36: =F22*(F$8<='Inputs & Summary'!$D$102) | G36: =G22*(G$8<='Inputs & Summary'!$D$102) | H36: =H22*(H$8<='Inputs & Summary'!$D$102) | I36: =I22*(I$8<='Inputs & Summary'!$D$102) | J36: =J22*(J$8<='Inputs & Summary'!$D$102) | K36: =K22*(K$8<='Inputs & Summary'!$D$102) | L36: =L22*(L$8<='Inputs & Summary'!$D$102) | ... DT36: =DT22*(DT$8<='Inputs & Summary'!$D$102)
B37: Unlevered Operating Cash Flow | E37: =SUM(E36) | F37: =SUM(F36) | G37: =SUM(G36) | H37: =SUM(H36) | I37: =SUM(I36) | J37: =SUM(J36) | K37: =SUM(K36) | L37: =SUM(L36) | ... DT37: =SUM(DT36)
B39: (+) Gross Sales Proceeds | E39: =IF(E$8='Inputs & Summary'!$D$102,'Inputs & Summary'!$O$5,0) | F39: =IF(F$8='Inputs & Summary'!$D$102,'Inputs & Summary'!$O$5,0) | G39: =IF(G$8='Inputs & Summary'!$D$102,'Inputs & Summary'!$O$5,0) | H39: =IF(H$8='Inputs & Summary'!$D$102,'Inputs & Summary'!$O$5,0) | I39: =IF(I$8='Inputs & Summary'!$D$102,'Inputs & Summary'!$O$5,0) | J39: =IF(J$8='Inputs & Summary'!$D$102,'Inputs & Summary'!$O$5,0) | K39: =IF(K$8='Inputs & Summary'!$D$102,'Inputs & Summary'!$O$5,0) | L39: =IF(L$8='Inputs & Summary'!$D$102,'Inputs & Summary'!$O$5,0) | ... DT39: =IF(DT$8='Inputs & Summary'!$D$102,'Inputs & Summary'!$O$5,0)
B40: (-) Sale Costs | E40: =-IF(E$8='Inputs & Summary'!$D$102,'Inputs & Summary'!$D$105*E39,0) | F40: =-IF(F$8='Inputs & Summary'!$D$102,'Inputs & Summary'!$D$105*F39,0) | G40: =-IF(G$8='Inputs & Summary'!$D$102,'Inputs & Summary'!$D$105*G39,0) | H40: =-IF(H$8='Inputs & Summary'!$D$102,'Inputs & Summary'!$D$105*H39,0) | I40: =-IF(I$8='Inputs & Summary'!$D$102,'Inputs & Summary'!$D$105*I39,0) | J40: =-IF(J$8='Inputs & Summary'!$D$102,'Inputs & Summary'!$D$105*J39,0) | K40: =-IF(K$8='Inputs & Summary'!$D$102,'Inputs & Summary'!$D$105*K39,0) | L40: =-IF(L$8='Inputs & Summary'!$D$102,'Inputs & Summary'!$D$105*L39,0) | ... DT40: =-IF(DT$8='Inputs & Summary'!$D$102,'Inputs & Summary'!$D$105*DT39,0)
B41: Total Unlevered Cash Flow | D41: =SUM(D34,D37,D39:D40) | E41: =SUM(E34,E37,E39:E40) | F41: =SUM(F34,F37,F39:F40) | G41: =SUM(G34,G37,G39:G40) | H41: =SUM(H34,H37,H39:H40) | I41: =SUM(I34,I37,I39:I40) | J41: =SUM(J34,J37,J39:J40) | K41: =SUM(K34,K37,K39:K40) | ... DT41: =SUM(DT34,DT37,DT39:DT40)
B42: Cumulative | D42: =SUM($D$41:D41) | E42: =SUM($D$41:E41) | F42: =SUM($D$41:F41) | G42: =SUM($D$41:G41) | H42: =SUM($D$41:H41) | I42: =SUM($D$41:I41) | J42: =SUM($D$41:J41) | K42: =SUM($D$41:K41) | ... DT42: =SUM($D$41:DT41)
B44: Unlevered Returns
...

Sheet Annual Proforma
B2: Date | C2: ='Inputs & Summary'!$D$20 | D2: =EOMONTH(C2,12) | E2: =EOMONTH(D2,12) | F2: =EOMONTH(E2,12) | G2: =EOMONTH(F2,12) | H2: =EOMONTH(G2,12) | I2: =EOMONTH(H2,12) | J2: =EOMONTH(I2,12) | K2: =EOMONTH(J2,12) | ... M2: =EOMONTH(L2,12)
B3: Year | C3: 0 | D3: =C3+1 | E3: =D3+1 | F3: =E3+1 | G3: =F3+1 | H3: =G3+1 | I3: =H3+1 | J3: =I3+1 | K3: =J3+1 | ... M3: =L3+1
B4: Unit Mix & Lease-Up
B5: ='Inputs & Summary'!F4 | D5: =SUMIF('Monthly Proforma'!$E$7:$DT$7,D$3,'Monthly Proforma'!$E10:$DT10) | E5: =SUMIF('Monthly Proforma'!$E$7:$DT$7,E$3,'Monthly Proforma'!$E10:$DT10) | F5: =SUMIF('Monthly Proforma'!$E$7:$DT$7,F$3,'Monthly Proforma'!$E10:$DT10) | G5: =SUMIF('Monthly Proforma'!$E$7:$DT$7,G$3,'Monthly Proforma'!$E10:$DT10) | H5: =SUMIF('Monthly Proforma'!$E$7:$DT$7,H$3,'Monthly Proforma'!$E10:$DT10) | I5: =SUMIF('Monthly Proforma'!$E$7:$DT$7,I$3,'Monthly Proforma'!$E10:$DT10) | J5: =SUMIF('Monthly Proforma'!$E$7:$DT$7,J$3,'Monthly Proforma'!$E10:$DT10) | K5: =SUMIF('Monthly Proforma'!$E$7:$DT$7,K$3,'Monthly Proforma'!$E10:$DT10) | ... M5: =SUMIF('Monthly Proforma'!$E$7:$DT$7,M$3,'Monthly Proforma'!$E10:$DT10)
B6: (+) Rental Income | D6: =SUM(D5:D5) | E6: =SUM(E5:E5) | F6: =SUM(F5:F5) | G6: =SUM(G5:G5) | H6: =SUM(H5:H5) | I6: =SUM(I5:I5) | J6: =SUM(J5:J5) | K6: =SUM(K5:K5) | ... M6: =SUM(M5:M5)
B7: Potential Gross Income | D7: =SUM(D6:D6) | E7: =SUM(E6:E6) | F7: =SUM(F6:F6) | G7: =SUM(G6:G6) | H7: =SUM(H6:H6) | I7: =SUM(I6:I6) | J7: =SUM(J6:J6) | K7: =SUM(K6:K6) | ... M7: =SUM(M6:M6)
B8: (-) General Vacancy | C8: ='Monthly Proforma'!D13 | D8: =SUMIF('Monthly Proforma'!$E$7:$DT$7,D$3,'Monthly Proforma'!$E13:$DT13) | E8: =SUMIF('Monthly Proforma'!$E$7:$DT$7,E$3,'Monthly Proforma'!$E13:$DT13) | F8: =SUMIF('Monthly Proforma'!$E$7:$DT$7,F$3,'Monthly Proforma'!$E13:$DT13) | G8: =SUMIF('Monthly Proforma'!$E$7:$DT$7,G$3,'Monthly Proforma'!$E13:$DT13) | H8: =SUMIF('Monthly Proforma'!$E$7:$DT$7,H$3,'Monthly Proforma'!$E13:$DT13) | I8: =SUMIF('Monthly Proforma'!$E$7:$DT$7,I$3,'Monthly Proforma'!$E13:$DT13) | J8: =SUMIF('Monthly Proforma'!$E$7:$DT$7,J$3,'Monthly Proforma'!$E13:$DT13) | K8: =SUMIF('Monthly Proforma'!$E$7:$DT$7,K$3,'Monthly Proforma'!$E13:$DT13) | ... M8: =SUMIF('Monthly Proforma'!$E$7:$DT$7,M$3,'Monthly Proforma'!$E13:$DT13)
B9: (-) Concessions | C9: ='Monthly Proforma'!D14 | D9: =SUMIF('Monthly Proforma'!$E$7:$DT$7,D$3,'Monthly Proforma'!$E14:$DT14) | E9: =SUMIF('Monthly Proforma'!$E$7:$DT$7,E$3,'Monthly Proforma'!$E14:$DT14) | F9: =SUMIF('Monthly Proforma'!$E$7:$DT$7,F$3,'Monthly Proforma'!$E14:$DT14) | G9: =SUMIF('Monthly Proforma'!$E$7:$DT$7,G$3,'Monthly Proforma'!$E14:$DT14) | H9: =SUMIF('Monthly Proforma'!$E$7:$DT$7,H$3,'Monthly Proforma'!$E14:$DT14) | I9: =SUMIF('Monthly Proforma'!$E$7:$DT$7,I$3,'Monthly Proforma'!$E14:$DT14) | J9: =SUMIF('Monthly Proforma'!$E$7:$DT$7,J$3,'Monthly Proforma'!$E14:$DT14) | K9: =SUMIF('Monthly Proforma'!$E$7:$DT$7,K$3,'Monthly Proforma'!$E14:$DT14) | ... M9: =SUMIF('Monthly Proforma'!$E$7:$DT$7,M$3,'Monthly Proforma'!$E14:$DT14)
B10: Effective Gross Income | D10: =SUM(D7:D9) | E10: =SUM(E7:E9) | F10: =SUM(F7:F9) | G10: =SUM(G7:G9) | H10: =SUM(H7:H9) | I10: =SUM(I7:I9) | J10: =SUM(J7:J9) | K10: =SUM(K7:K9) | ... M10: =SUM(M7:M9)
B11: (-) Property Taxes | C11: ='Monthly Proforma'!D16 | D11: =SUMIF('Monthly Proforma'!$E$7:$DT$7,D$3,'Monthly Proforma'!$E16:$DT16) | E11: =SUMIF('Monthly Proforma'!$E$7:$DT$7,E$3,'Monthly Proforma'!$E16:$DT16) | F11: =SUMIF('Monthly Proforma'!$E$7:$DT$7,F$3,'Monthly Proforma'!$E16:$DT16) | G11: =SUMIF('Monthly Proforma'!$E$7:$DT$7,G$3,'Monthly Proforma'!$E16:$DT16) | H11: =SUMIF('Monthly Proforma'!$E$7:$DT$7,H$3,'Monthly Proforma'!$E16:$DT16) | I11: =SUMIF('Monthly Proforma'!$E$7:$DT$7,I$3,'Monthly Proforma'!$E16:$DT16) | J11: =SUMIF('Monthly Proforma'!$E$7:$DT$7,J$3,'Monthly Proforma'!$E16:$DT16) | K11: =SUMIF('Monthly Proforma'!$E$7:$DT$7,K$3,'Monthly Proforma'!$E16:$DT16) | ... M11: =SUMIF('Monthly Proforma'!$E$7:$DT$7,M$3,'Monthly Proforma'!$E16:$DT16)
B12: (-) Insurance | C12: ='Monthly Proforma'!D17 | D12: =SUMIF('Monthly Proforma'!$E$7:$DT$7,D$3,'Monthly Proforma'!$E17:$DT17) | E12: =SUMIF('Monthly Proforma'!$E$7:$DT$7,E$3,'Monthly Proforma'!$E17:$DT17) | F12: =SUMIF('Monthly Proforma'!$E$7:$DT$7,F$3,'Monthly Proforma'!$E17:$DT17) | G12: =SUMIF('Monthly Proforma'!$E$7:$DT$7,G$3,'Monthly Proforma'!$E17:$DT17) | H12: =SUMIF('Monthly Proforma'!$E$7:$DT$7,H$3,'Monthly Proforma'!$E17:$DT17) | I12: =SUMIF('Monthly Proforma'!$E$7:$DT$7,I$3,'Monthly Proforma'!$E17:$DT17) | J12: =SUMIF('Monthly Proforma'!$E$7:$DT$7,J$3,'Monthly Proforma'!$E17:$DT17) | K12: =SUMIF('Monthly Proforma'!$E$7:$DT$7,K$3,'Monthly Proforma'!$E17:$DT17) | ... M12: =SUMIF('Monthly Proforma'!$E$7:$DT$7,M$3,'Monthly Proforma'!$E17:$DT17)
B13: (-) Management | C13: ='Monthly Proforma'!D18 | D13: =SUMIF('Monthly Proforma'!$E$7:$DT$7,D$3,'Monthly Proforma'!$E18:$DT18) | E13: =SUMIF('Monthly Proforma'!$E$7:$DT$7,E$3,'Monthly Proforma'!$E18:$DT18) | F13: =SUMIF('Monthly Proforma'!$E$7:$DT$7,F$3,'Monthly Proforma'!$E18:$DT18) | G13: =SUMIF('Monthly Proforma'!$E$7:$DT$7,G$3,'Monthly Proforma'!$E18:$DT18) | H13: =SUMIF('Monthly Proforma'!$E$7:$DT$7,H$3,'Monthly Proforma'!$E18:$DT18) | I13: =SUMIF('Monthly Proforma'!$E$7:$DT$7,I$3,'Monthly Proforma'!$E18:$DT18) | J13: =SUMIF('Monthly Proforma'!$E$7:$DT$7,J$3,'Monthly Proforma'!$E18:$DT18) | K13: =SUMIF('Monthly Proforma'!$E$7:$DT$7,K$3,'Monthly Proforma'!$E18:$DT18) | ... M13: =SUMIF('Monthly Proforma'!$E$7:$DT$7,M$3,'Monthly Proforma'!$E18:$DT18)
B14: (-) Utilities & HOA Dues | C14: ='Monthly Proforma'!D19 | D14: =SUMIF('Monthly Proforma'!$E$7:$DT$7,D$3,'Monthly Proforma'!$E19:$DT19) | E14: =SUMIF('Monthly Proforma'!$E$7:$DT$7,E$3,'Monthly Proforma'!$E19:$DT19) | F14: =SUMIF('Monthly Proforma'!$E$7:$DT$7,F$3,'Monthly Proforma'!$E19:$DT19) | G14: =SUMIF('Monthly Proforma'!$E$7:$DT$7,G$3,'Monthly Proforma'!$E19:$DT19) | H14: =SUMIF('Monthly Proforma'!$E$7:$DT$7,H$3,'Monthly Proforma'!$E19:$DT19) | I14: =SUMIF('Monthly Proforma'!$E$7:$DT$7,I$3,'Monthly Proforma'!$E19:$DT19) | J14: =SUMIF('Monthly Proforma'!$E$7:$DT$7,J$3,'Monthly Proforma'!$E19:$DT19) | K14: =SUMIF('Monthly Proforma'!$E$7:$DT$7,K$3,'Monthly Proforma'!$E19:$DT19) | ... M14: =SUMIF('Monthly Proforma'!$E$7:$DT$7,M$3,'Monthly Proforma'!$E19:$DT19)
B15: (-) Maintenance & Repairs | C15: ='Monthly Proforma'!D20 | D15: =SUMIF('Monthly Proforma'!$E$7:$DT$7,D$3,'Monthly Proforma'!$E20:$DT20) | E15: =SUMIF('Monthly Proforma'!$E$7:$DT$7,E$3,'Monthly Proforma'!$E20:$DT20) | F15: =SUMIF('Monthly Proforma'!$E$7:$DT$7,F$3,'Monthly Proforma'!$E20:$DT20) | G15: =SUMIF('Monthly Proforma'!$E$7:$DT$7,G$3,'Monthly Proforma'!$E20:$DT20) | H15: =SUMIF('Monthly Proforma'!$E$7:$DT$7,H$3,'Monthly Proforma'!$E20:$DT20) | I15: =SUMIF('Monthly Proforma'!$E$7:$DT$7,I$3,'Monthly Proforma'!$E20:$DT20) | J15: =SUMIF('Monthly Proforma'!$E$7:$DT$7,J$3,'Monthly Proforma'!$E20:$DT20) | K15: =SUMIF('Monthly Proforma'!$E$7:$DT$7,K$3,'Monthly Proforma'!$E20:$DT20) | ... M15: =SUMIF('Monthly Proforma'!$E$7:$DT$7,M$3,'Monthly Proforma'!$E20:$DT20)
B16: (-) Advertising, Admin & Payroll | C16: ='Monthly Proforma'!D21 | D16: =SUMIF('Monthly Proforma'!$E$7:$DT$7,D$3,'Monthly Proforma'!$E21:$DT21) | E16: =SUMIF('Monthly Proforma'!$E$7:$DT$7,E$3,'Monthly Proforma'!$E21:$DT21) | F16: =SUMIF('Monthly Proforma'!$E$7:$DT$7,F$3,'Monthly Proforma'!$E21:$DT21) | G16: =SUMIF('Monthly Proforma'!$E$7:$DT$7,G$3,'Monthly Proforma'!$E21:$DT21) | H16: =SUMIF('Monthly Proforma'!$E$7:$DT$7,H$3,'Monthly Proforma'!$E21:$DT21) | I16: =SUMIF('Monthly Proforma'!$E$7:$DT$7,I$3,'Monthly Proforma'!$E21:$DT21) | J16: =SUMIF('Monthly Proforma'!$E$7:$DT$7,J$3,'Monthly Proforma'!$E21:$DT21) | K16: =SUMIF('Monthly Proforma'!$E$7:$DT$7,K$3,'Monthly Proforma'!$E21:$DT21) | ... M16: =SUMIF('Monthly Proforma'!$E$7:$DT$7,M$3,'Monthly Proforma'!$E21:$DT21)
B17: Net Operating Income | D17: =SUM(D10:D16) | E17: =SUM(E10:E16) | F17: =SUM(F10:F16) | G17: =SUM(G10:G16) | H17: =SUM(H10:H16) | I17: =SUM(I10:I16) | J17: =SUM(J10:J16) | K17: =SUM(K10:K16) | ... M17: =SUM(M10:M16)
B18: NOI Margin | D18: =D17/D7 | E18: =E17/E7 | F18: =F17/F7 | G18: =G17/G7 | H18: =H17/H7 | I18: =I17/I7 | J18: =J17/J7 | K18: =K17/K7 | ... M18: =M17/M7
B19: NOI Growth | E19: =E17/D17-1 | F19: =F17/E17-1 | G19: =G17/F17-1 | H19: =H17/G17-1 | I19: =I17/H17-1 | J19: =J17/I17-1 | K19: =K17/J17-1 | L19: =L17/K17-1 | M19: =M17/L17-1
B20: NOI Yield | D20: =(D17/-$C$31)*(D$3<='Inputs & Summary'!$O$4) | E20: =(E17/-$C$31)*(E$3<='Inputs & Summary'!$O$4) | F20: =(F17/-$C$31)*(F$3<='Inputs & Summary'!$O$4) | G20: =(G17/-$C$31)*(G$3<='Inputs & Summary'!$O$4) | H20: =(H17/-$C$31)*(H$3<='Inputs & Summary'!$O$4) | I20: =(I17/-$C$31)*(I$3<='Inputs & Summary'!$O$4) | J20: =(J17/-$C$31)*(J$3<='Inputs & Summary'!$O$4) | K20: =(K17/-$C$31)*(K$3<='Inputs & Summary'!$O$4) | ... M20: =(M17/-$C$31)*(M$3<='Inputs & Summary'!$O$4)
B21: (-) Debt Service | C21: ='Monthly Proforma'!D24 | D21: =SUMIF('Monthly Proforma'!$E$7:$DT$7,D$3,'Monthly Proforma'!$E24:$DT24) | E21: =SUMIF('Monthly Proforma'!$E$7:$DT$7,E$3,'Monthly Proforma'!$E24:$DT24) | F21: =SUMIF('Monthly Proforma'!$E$7:$DT$7,F$3,'Monthly Proforma'!$E24:$DT24) | G21: =SUMIF('Monthly Proforma'!$E$7:$DT$7,G$3,'Monthly Proforma'!$E24:$DT24) | H21: =SUMIF('Monthly Proforma'!$E$7:$DT$7,H$3,'Monthly Proforma'!$E24:$DT24) | I21: =SUMIF('Monthly Proforma'!$E$7:$DT$7,I$3,'Monthly Proforma'!$E24:$DT24) | J21: =SUMIF('Monthly Proforma'!$E$7:$DT$7,J$3,'Monthly Proforma'!$E24:$DT24) | K21: =SUMIF('Monthly Proforma'!$E$7:$DT$7,K$3,'Monthly Proforma'!$E24:$DT24) | ... M21: =SUMIF('Monthly Proforma'!$E$7:$DT$7,M$3,'Monthly Proforma'!$E24:$DT24)
B22: Annual Cash Flow | D22: =D17+D21 | E22: =E17+E21 | F22: =F17+F21 | G22: =G17+G21 | H22: =H17+H21 | I22: =I17+I21 | J22: =J17+J21 | K22: =K17+K21 | ... M22: =M17+M21
B23: DSCR | D23: =-D17/D21 | E23: =-E17/E21 | F23: =-F17/F21 | G23: =-G17/G21 | H23: =-H17/H21 | I23: =-I17/I21 | J23: =-J17/J21 | K23: =-K17/K21 | ... M23: =-M17/M21
B25: Unlevered Cash Flow
B26: (-) Purchase Price | C26: ='Monthly Proforma'!D29 | D26: =SUMIF('Monthly Proforma'!$E$7:$DT$7,D$3,'Monthly Proforma'!$E29:$DT29) | E26: =SUMIF('Monthly Proforma'!$E$7:$DT$7,E$3,'Monthly Proforma'!$E29:$DT29) | F26: =SUMIF('Monthly Proforma'!$E$7:$DT$7,F$3,'Monthly Proforma'!$E29:$DT29) | G26: =SUMIF('Monthly Proforma'!$E$7:$DT$7,G$3,'Monthly Proforma'!$E29:$DT29) | H26: =SUMIF('Monthly Proforma'!$E$7:$DT$7,H$3,'Monthly Proforma'!$E29:$DT29) | I26: =SUMIF('Monthly Proforma'!$E$7:$DT$7,I$3,'Monthly Proforma'!$E29:$DT29) | J26: =SUMIF('Monthly Proforma'!$E$7:$DT$7,J$3,'Monthly Proforma'!$E29:$DT29) | K26: =SUMIF('Monthly Proforma'!$E$7:$DT$7,K$3,'Monthly Proforma'!$E29:$DT29) | ... M26: =SUMIF('Monthly Proforma'!$E$7:$DT$7,M$3,'Monthly Proforma'!$E29:$DT29)
B27: ='Monthly Proforma'!B30 | C27: ='Monthly Proforma'!D30 | D27: =SUMIF('Monthly Proforma'!$E$7:$DT$7,D$3,'Monthly Proforma'!$E30:$DT30) | E27: =SUMIF('Monthly Proforma'!$E$7:$DT$7,E$3,'Monthly Proforma'!$E30:$DT30) | F27: =SUMIF('Monthly Proforma'!$E$7:$DT$7,F$3,'Monthly Proforma'!$E30:$DT30) | G27: =SUMIF('Monthly Proforma'!$E$7:$DT$7,G$3,'Monthly Proforma'!$E30:$DT30) | H27: =SUMIF('Monthly Proforma'!$E$7:$DT$7,H$3,'Monthly Proforma'!$E30:$DT30) | I27: =SUMIF('Monthly Proforma'!$E$7:$DT$7,I$3,'Monthly Proforma'!$E30:$DT30) | J27: =SUMIF('Monthly Proforma'!$E$7:$DT$7,J$3,'Monthly Proforma'!$E30:$DT30) | K27: =SUMIF('Monthly Proforma'!$E$7:$DT$7,K$3,'Monthly Proforma'!$E30:$DT30) | ... M27: =SUMIF('Monthly Proforma'!$E$7:$DT$7,M$3,'Monthly Proforma'!$E30:$DT30)
B28: ='Monthly Proforma'!B31 | C28: ='Monthly Proforma'!D31 | D28: =SUMIF('Monthly Proforma'!$E$7:$DT$7,D$3,'Monthly Proforma'!$E31:$DT31) | E28: =SUMIF('Monthly Proforma'!$E$7:$DT$7,E$3,'Monthly Proforma'!$E31:$DT31) | F28: =SUMIF('Monthly Proforma'!$E$7:$DT$7,F$3,'Monthly Proforma'!$E31:$DT31) | G28: =SUMIF('Monthly Proforma'!$E$7:$DT$7,G$3,'Monthly Proforma'!$E31:$DT31) | H28: =SUMIF('Monthly Proforma'!$E$7:$DT$7,H$3,'Monthly Proforma'!$E31:$DT31) | I28: =SUMIF('Monthly Proforma'!$E$7:$DT$7,I$3,'Monthly Proforma'!$E31:$DT31) | J28: =SUMIF('Monthly Proforma'!$E$7:$DT$7,J$3,'Monthly Proforma'!$E31:$DT31) | K28: =SUMIF('Monthly Proforma'!$E$7:$DT$7,K$3,'Monthly Proforma'!$E31:$DT31) | ... M28: =SUMIF('Monthly Proforma'!$E$7:$DT$7,M$3,'Monthly Proforma'!$E31:$DT31)
B29: ='Monthly Proforma'!B32 | C29: ='Monthly Proforma'!D32 | D29: =SUMIF('Monthly Proforma'!$E$7:$DT$7,D$3,'Monthly Proforma'!$E32:$DT32) | E29: =SUMIF('Monthly Proforma'!$E$7:$DT$7,E$3,'Monthly Proforma'!$E32:$DT32) | F29: =SUMIF('Monthly Proforma'!$E$7:$DT$7,F$3,'Monthly Proforma'!$E32:$DT32) | G29: =SUMIF('Monthly Proforma'!$E$7:$DT$7,G$3,'Monthly Proforma'!$E32:$DT32) | H29: =SUMIF('Monthly Proforma'!$E$7:$DT$7,H$3,'Monthly Proforma'!$E32:$DT32) | I29: =SUMIF('Monthly Proforma'!$E$7:$DT$7,I$3,'Monthly Proforma'!$E32:$DT32) | J29: =SUMIF('Monthly Proforma'!$E$7:$DT$7,J$3,'Monthly Proforma'!$E32:$DT32) | K29: =SUMIF('Monthly Proforma'!$E$7:$DT$7,K$3,'Monthly Proforma'!$E32:$DT32) | ... M29: =SUMIF('Monthly Proforma'!$E$7:$DT$7,M$3,'Monthly Proforma'!$E32:$DT32)
B30: ='Monthly Proforma'!B33 | C30: ='Monthly Proforma'!D33 | D30: =SUMIF('Monthly Proforma'!$E$7:$DT$7,D$3,'Monthly Proforma'!$E33:$DT33) | E30: =SUMIF('Monthly Proforma'!$E$7:$DT$7,E$3,'Monthly Proforma'!$E33:$DT33) | F30: =SUMIF('Monthly Proforma'!$E$7:$DT$7,F$3,'Monthly Proforma'!$E33:$DT33) | G30: =SUMIF('Monthly Proforma'!$E$7:$DT$7,G$3,'Monthly Proforma'!$E33:$DT33) | H30: =SUMIF('Monthly Proforma'!$E$7:$DT$7,H$3,'Monthly Proforma'!$E33:$DT33) | I30: =SUMIF('Monthly Proforma'!$E$7:$DT$7,I$3,'Monthly Proforma'!$E33:$DT33) | J30: =SUMIF('Monthly Proforma'!$E$7:$DT$7,J$3,'Monthly Proforma'!$E33:$DT33) | K30: =SUMIF('Monthly Proforma'!$E$7:$DT$7,K$3,'Monthly Proforma'!$E33:$DT33) | ... M30: =SUMIF('Monthly Proforma'!$E$7:$DT$7,M$3,'Monthly Proforma'!$E33:$DT33)
B31: Total Unlevered Costs | C31: =SUM(C26:C30) | D31: =SUM(D26:D27) | E31: =SUM(E26:E27) | F31: =SUM(F26:F27) | G31: =SUM(G26:G27) | H31: =SUM(H26:H27) | I31: =SUM(I26:I27) | J31: =SUM(J26:J27) | K31: =SUM(K26:K27) | ... M31: =SUM(M26:M27)
B33: (+) Net Operating Income | D33: =SUMIF('Monthly Proforma'!$E$7:$DT$7,D$3,'Monthly Proforma'!$E36:$DT36) | E33: =SUMIF('Monthly Proforma'!$E$7:$DT$7,E$3,'Monthly Proforma'!$E36:$DT36) | F33: =SUMIF('Monthly Proforma'!$E$7:$DT$7,F$3,'Monthly Proforma'!$E36:$DT36) | G33: =SUMIF('Monthly Proforma'!$E$7:$DT$7,G$3,'Monthly Proforma'!$E36:$DT36) | H33: =SUMIF('Monthly Proforma'!$E$7:$DT$7,H$3,'Monthly Proforma'!$E36:$DT36) | I33: =SUMIF('Monthly Proforma'!$E$7:$DT$7,I$3,'Monthly Proforma'!$E36:$DT36) | J33: =SUMIF('Monthly Proforma'!$E$7:$DT$7,J$3,'Monthly Proforma'!$E36:$DT36) | K33: =SUMIF('Monthly Proforma'!$E$7:$DT$7,K$3,'Monthly Proforma'!$E36:$DT36) | ... M33: =SUMIF('Monthly Proforma'!$E$7:$DT$7,M$3,'Monthly Proforma'!$E36:$DT36)
B34: Unlevered Operating Cash Flow | D34: =SUM(D33:D33) | E34: =SUM(E33:E33) | F34: =SUM(F33:F33) | G34: =SUM(G33:G33) | H34: =SUM(H33:H33) | I34: =SUM(I33:I33) | J34: =SUM(J33:J33) | K34: =SUM(K33:K33) | ... M34: =SUM(M33:M33)
B36: (+) Gross Sales Proceeds | D36: =SUMIF('Monthly Proforma'!$E$7:$DT$7,D$3,'Monthly Proforma'!$E39:$DT39) | E36: =SUMIF('Monthly Proforma'!$E$7:$DT$7,E$3,'Monthly Proforma'!$E39:$DT39) | F36: =SUMIF('Monthly Proforma'!$E$7:$DT$7,F$3,'Monthly Proforma'!$E39:$DT39) | G36: =SUMIF('Monthly Proforma'!$E$7:$DT$7,G$3,'Monthly Proforma'!$E39:$DT39) | H36: =SUMIF('Monthly Proforma'!$E$7:$DT$7,H$3,'Monthly Proforma'!$E39:$DT39) | I36: =SUMIF('Monthly Proforma'!$E$7:$DT$7,I$3,'Monthly Proforma'!$E39:$DT39) | J36: =SUMIF('Monthly Proforma'!$E$7:$DT$7,J$3,'Monthly Proforma'!$E39:$DT39) | K36: =SUMIF('Monthly Proforma'!$E$7:$DT$7,K$3,'Monthly Proforma'!$E39:$DT39) | ... M36: =SUMIF('Monthly Proforma'!$E$7:$DT$7,M$3,'Monthly Proforma'!$E39:$DT39)
B37: (-) Sale Costs | D37: =SUMIF('Monthly Proforma'!$E$7:$DT$7,D$3,'Monthly Proforma'!$E40:$DT40) | E37: =SUMIF('Monthly Proforma'!$E$7:$DT$7,E$3,'Monthly Proforma'!$E40:$DT40) | F37: =SUMIF('Monthly Proforma'!$E$7:$DT$7,F$3,'Monthly Proforma'!$E40:$DT40) | G37: =SUMIF('Monthly Proforma'!$E$7:$DT$7,G$3,'Monthly Proforma'!$E40:$DT40) | H37: =SUMIF('Monthly Proforma'!$E$7:$DT$7,H$3,'Monthly Proforma'!$E40:$DT40) | I37: =SUMIF('Monthly Proforma'!$E$7:$DT$7,I$3,'Monthly Proforma'!$E40:$DT40) | J37: =SUMIF('Monthly Proforma'!$E$7:$DT$7,J$3,'Monthly Proforma'!$E40:$DT40) | K37: =SUMIF('Monthly Proforma'!$E$7:$DT$7,K$3,'Monthly Proforma'!$E40:$DT40) | ... M37: =SUMIF('Monthly Proforma'!$E$7:$DT$7,M$3,'Monthly Proforma'!$E40:$DT40)
B38: Total Unlevered Cash Flow | C38: =SUM(C31,C34,C36:C37) | D38: =SUM(D36:D37,D34) | E38: =SUM(E36:E37,E34) | F38: =SUM(F36:F37,F34) | G38: =SUM(G36:G37,G34) | H38: =SUM(H36:H37,H34) | I38: =SUM(I36:I37,I34) | J38: =SUM(J36:J37,J34) | K38: =SUM(K36:K37,K34) | ... M38: =SUM(M36:M37,M34)
B39: Cumulative | C39: =SUM($C$38:C38) | D39: =SUM($C$38:D38) | E39: =SUM($C$38:E38) | F39: =SUM($C$38:F38) | G39: =SUM($C$38:G38) | H39: =SUM($C$38:H38) | I39: =SUM($C$38:I38) | J39: =SUM($C$38:J38) | ... M39: =SUM($C$38:M38)
B41: Unlevered Returns
B42: IRR | C42: ='Monthly Proforma'!C45
B43: Equity Multiple | C43: ='Monthly Proforma'!C46
B44: Net Profit | C44: ='Monthly Proforma'!C47
B45: Peak Equity | C45: ='Monthly Proforma'!C48
...

Sheet Amortization Schedule - Annual
B2: Year | C2: Beg Balance | D2: Principal PMT | E2: Interest PMT | F2: Ending Balance
B3: 1 | C3: ='Inputs & Summary'!P12 | D3: =PPMT(LoanRate,$B3,LoanAmortization,-LoanAmount) | E3: =IPMT(LoanRate,$B3,LoanAmortization,-LoanAmount) | F3: =C3-D3
B4: =B3+1 | C4: =F3 | D4: =PPMT(LoanRate,$B4,LoanAmortization,-LoanAmount) | E4: =IPMT(LoanRate,$B4,LoanAmortization,-LoanAmount) | F4: =C4-D4
B5: =B4+1 | C5: =F4 | D5: =PPMT(LoanRate,$B5,LoanAmortization,-LoanAmount) | E5: =IPMT(LoanRate,$B5,LoanAmortization,-LoanAmount) | F5: =C5-D5
B6: =B5+1 | C6: =F5 | D6: =PPMT(LoanRate,$B6,LoanAmortization,-LoanAmount) | E6: =IPMT(LoanRate,$B6,LoanAmortization,-LoanAmount) | F6: =C6-D6
B7: =B6+1 | C7: =F6 | D7: =PPMT(LoanRate,$B7,LoanAmortization,-LoanAmount) | E7: =IPMT(LoanRate,$B7,LoanAmortization,-LoanAmount) | F7: =C7-D7
B8: =B7+1 | C8: =F7 | D8: =PPMT(LoanRate,$B8,LoanAmortization,-LoanAmount) | E8: =IPMT(LoanRate,$B8,LoanAmortization,-LoanAmount) | F8: =C8-D8
B9: =B8+1 | C9: =F8 | D9: =PPMT(LoanRate,$B9,LoanAmortization,-LoanAmount) | E9: =IPMT(LoanRate,$B9,LoanAmortization,-LoanAmount) | F9: =C9-D9
B10: =B9+1 | C10: =F9 | D10: =PPMT(LoanRate,$B10,LoanAmortization,-LoanAmount) | E10: =IPMT(LoanRate,$B10,LoanAmortization,-LoanAmount) | F10: =C10-D10
B11: =B10+1 | C11: =F10 | D11: =PPMT(LoanRate,$B11,LoanAmortization,-LoanAmount) | E11: =IPMT(LoanRate,$B11,LoanAmortization,-LoanAmount) | F11: =C11-D11
B12: =B11+1 | C12: =F11 | D12: =PPMT(LoanRate,$B12,LoanAmortization,-LoanAmount) | E12: =IPMT(LoanRate,$B12,LoanAmortization,-LoanAmount) | F12: =C12-D12
B13: =B12+1 | C13: =F12 | D13: =PPMT(LoanRate,$B13,LoanAmortization,-LoanAmount) | E13: =IPMT(LoanRate,$B13,LoanAmortization,-LoanAmount) | F13: =C13-D13
B14: =B13+1 | C14: =F13 | D14: =PPMT(LoanRate,$B14,LoanAmortization,-LoanAmount) | E14: =IPMT(LoanRate,$B14,LoanAmortization,-LoanAmount) | F14: =C14-D14
B15: =B14+1 | C15: =F14 | D15: =PPMT(LoanRate,$B15,LoanAmortization,-LoanAmount) | E15: =IPMT(LoanRate,$B15,LoanAmortization,-LoanAmount) | F15: =C15-D15
... B32: =B31+1 | C32: =F31 | D32: =PPMT(LoanRate,$B32,LoanAmortization,-LoanAmount) | E32: =IPMT(LoanRate,$B32,LoanAmortization,-LoanAmount) | F32: =C32-D32

Sheet Amortization Schedule - Monthly
B2: Month | C2: Beg Balance | D2: Principal PMT | E2: Interest PMT | F2: Ending Balance
B3: 1 | C3: ='Inputs & Summary'!P12 | D3: =PPMT(LoanRate/12,$B3,LoanAmortization*12,-LoanAmount) | E3: =IPMT(LoanRate/12,$B3,LoanAmortization*12,-LoanAmount) | F3: =C3-D3
B4: =B3+1 | C4: =F3 | D4: =PPMT(LoanRate/12,$B4,LoanAmortization*12,-LoanAmount) | E4: =IPMT(LoanRate/12,$B4,LoanAmortization*12,-LoanAmount) | F4: =C4-D4
B5: =B4+1 | C5: =F4 | D5: =PPMT(LoanRate/12,$B5,LoanAmortization*12,-LoanAmount) | E5: =IPMT(LoanRate/12,$B5,LoanAmortization*12,-LoanAmount) | F5: =C5-D5
B6: =B5+1 | C6: =F5 | D6: =PPMT(LoanRate/12,$B6,LoanAmortization*12,-LoanAmount) | E6: =IPMT(LoanRate/12,$B6,LoanAmortization*12,-LoanAmount) | F6: =C6-D6
B7: =B6+1 | C7: =F6 | D7: =PPMT(LoanRate/12,$B7,LoanAmortization*12,-LoanAmount) | E7: =IPMT(LoanRate/12,$B7,LoanAmortization*12,-LoanAmount) | F7: =C7-D7
B8: =B7+1 | C8: =F7 | D8: =PPMT(LoanRate/12,$B8,LoanAmortization*12,-LoanAmount) | E8: =IPMT(LoanRate/12,$B8,LoanAmortization*12,-LoanAmount) | F8: =C8-D8
B9: =B8+1 | C9: =F8 | D9: =PPMT(LoanRate/12,$B9,LoanAmortization*12,-LoanAmount) | E9: =IPMT(LoanRate/12,$B9,LoanAmortization*12,-LoanAmount) | F9: =C9-D9
B10: =B9+1 | C10: =F9 | D10: =PPMT(LoanRate/12,$B10,LoanAmortization*12,-LoanAmount) | E10: =IPMT(LoanRate/12,$B10,LoanAmortization*12,-LoanAmount) | F10: =C10-D10
B11: =B10+1 | C11: =F10 | D11: =PPMT(LoanRate/12,$B11,LoanAmortization*12,-LoanAmount) | E11: =IPMT(LoanRate/12,$B11,LoanAmortization*12,-LoanAmount) | F11: =C11-D11
B12: =B11+1 | C12: =F11 | D12: =PPMT(LoanRate/12,$B12,LoanAmortization*12,-LoanAmount) | E12: =IPMT(LoanRate/12,$B12,LoanAmortization*12,-LoanAmount) | F12: =C12-D12
B13: =B12+1 | C13: =F12 | D13: =PPMT(LoanRate/12,$B13,LoanAmortization*12,-LoanAmount) | E13: =IPMT(LoanRate/12,$B13,LoanAmortization*12,-LoanAmount) | F13: =C13-D13
B14: =B13+1 | C14: =F13 | D14: =PPMT(LoanRate/12,$B14,LoanAmortization*12,-LoanAmount) | E14: =IPMT(LoanRate/12,$B14,LoanAmortization*12,-LoanAmount) | F14: =C14-D14
B15: =B14+1 | C15: =F14 | D15: =PPMT(LoanRate/12,$B15,LoanAmortization*12,-LoanAmount) | E15: =IPMT(LoanRate/12,$B15,LoanAmortization*12,-LoanAmount) | F15: =C15-D15
... B362: =B361+1 | C362: =F361 | D362: =PPMT(LoanRate/12,$B362,LoanAmortization*12,-LoanAmount) | E362: =IPMT(LoanRate/12,$B362,LoanAmortization*12,-LoanAmount) | F362: =C362-D362
